<?xml version="1.0" ?>
<!-- =================================================================================== -->
<!-- |    This document was autogenerated by xacro from /home/gepetto/ros2_ws/install/franka_description/share/franka_description/robots/fer/fer.urdf.xacro | -->
<!-- |    EDITING THIS FILE BY HAND IS NOT RECOMMENDED                                 | -->
<!-- =================================================================================== -->
<robot name="fer">
  <!-- safety_distance: Minimum safety distance in [m] by which the collision volumes are expanded and which is enforced during robot motions -->
  <!-- arm_id: Namespace of the robot arm. Serves to differentiate between arms in case of multiple instances. -->
  <!-- joint_limits: description of the joint limits that comes from a YAML file. Example definition: ${xacro.load_yaml('$(find franka_description)/robots/fr3/joint_limits.yaml')} -->
  <!-- kinematics: description of the kinematics that comes from a YAML file. Example definition: ${xacro.load_yaml('$(find franka_description)/robots/fr3/kinematics.yaml')} -->
  <!-- inertials: description of the inertials that comes from a YAML file. Example definition: ${xacro.load_yaml('$(find franka_description)/robots/fr3/inertials.yaml')} -->
  <!-- dynamics: description of the dynamics that comes from a YAML file. Example definition: ${xacro.load_yaml('$(find franka_description)/robots/fr3/dynamics.yaml')} -->
  <!-- sub-link defining detailed meshes for collision with environment -->
  <link name="fer_link0">
    <visual name="fer_link0_visual">
      <geometry>
        <mesh filename="package://models/fer/meshes/visual/link0.dae"/>
      </geometry>
    </visual>
    <collision name="fer_link0_collision">
      <geometry>
        <mesh filename="package://models/fer/meshes/collision/link0.obj"/>
      </geometry>
    </collision>
    <inertial>
      <origin rpy="0 0 0" xyz="-0.041018 -0.00014 0.049974"/>
      <mass value="0.629769"/>
      <inertia ixx="0.00315" ixy="8.2904e-07" ixz="0.00015" iyy="0.00388" iyz="8.2299e-06" izz="0.004285"/>
    </inertial>
  </link>
  <!-- sub-link defining detailed meshes for collision with environment -->
  <link name="fer_link1">
    <visual name="fer_link1_visual">
      <geometry>
        <mesh filename="package://models/fer/meshes/visual/link1.dae"/>
      </geometry>
    </visual>
    <collision name="fer_link1_collision">
      <geometry>
        <mesh filename="package://models/fer/meshes/collision/link1.obj"/>
      </geometry>
    </collision>
    <inertial>
      <origin rpy="0 0 0" xyz="0.003875 0.002081 -0.04762"/>
      <mass value="4.970684"/>
      <inertia ixx="0.70337" ixy="-0.000139" ixz="0.006772" iyy="0.70661" iyz="0.019169" izz="0.009117"/>
    </inertial>
  </link>
  <joint name="fer_joint1" type="revolute">
    <origin rpy="0 0 0" xyz="0 0 0.333"/>
    <parent link="fer_link0"/>
    <child link="fer_link1"/>
    <axis xyz="0 0 1"/>
    <limit effort="87.0" lower="-2.8973" upper="2.8973" velocity="2.175"/>
    <safety_controller k_position="100.0" k_velocity="40.0" soft_lower_limit="-2.8973" soft_upper_limit="2.8973"/>
    <dynamics D="1" K="7000" damping="0.003" friction="0.2" mu_coulomb="0" mu_viscous="16"/>
  </joint>
  <!-- sub-link defining detailed meshes for collision with environment -->
  <link name="fer_link2">
    <visual name="fer_link2_visual">
      <geometry>
        <mesh filename="package://models/fer/meshes/visual/link2.dae"/>
      </geometry>
    </visual>
    <collision name="fer_link2_collision">
      <geometry>
        <mesh filename="package://models/fer/meshes/collision/link2.obj"/>
      </geometry>
    </collision>
    <inertial>
      <origin rpy="0 0 0" xyz="-0.003141 -0.02872  0.003495"/>
      <mass value="0.646926"/>
      <inertia ixx="0.007962" ixy="-0.003925" ixz="0.010254" iyy="0.02811" iyz="0.000704" izz="0.025995"/>
    </inertial>
  </link>
  <joint name="fer_joint2" type="revolute">
    <origin rpy="-1.570796326794897 0 0" xyz="0 0 0"/>
    <parent link="fer_link1"/>
    <child link="fer_link2"/>
    <axis xyz="0 0 1"/>
    <limit effort="87.0" lower="-1.7628" upper="1.7628" velocity="2.175"/>
    <safety_controller k_position="100.0" k_velocity="40.0" soft_lower_limit="-1.7628" soft_upper_limit="1.7628"/>
    <dynamics D="1" K="7000" damping="0.003" friction="0.2" mu_coulomb="0" mu_viscous="16"/>
  </joint>
  <!-- sub-link defining detailed meshes for collision with environment -->
  <link name="fer_link3">
    <visual name="fer_link3_visual">
      <geometry>
        <mesh filename="package://models/fer/meshes/visual/link3.dae"/>
      </geometry>
    </visual>
    <collision name="fer_link3_collision">
      <geometry>
        <mesh filename="package://models/fer/meshes/collision/link3.obj"/>
      </geometry>
    </collision>
    <inertial>
      <origin rpy="0 0 0" xyz="2.7518e-02 3.9252e-02 -6.6502e-02"/>
      <mass value="3.228604"/>
      <inertia ixx="0.037242" ixy="-0.004761" ixz="-0.011396" iyy="0.036155" iyz="-0.012805" izz="0.01083"/>
    </inertial>
  </link>
  <joint name="fer_joint3" type="revolute">
    <origin rpy="1.570796326794897 0 0" xyz="0 -0.316 0"/>
    <parent link="fer_link2"/>
    <child link="fer_link3"/>
    <axis xyz="0 0 1"/>
    <limit effort="87.0" lower="-2.8973" upper="2.8973" velocity="2.175"/>
    <safety_controller k_position="100.0" k_velocity="40.0" soft_lower_limit="-2.8973" soft_upper_limit="2.8973"/>
    <dynamics D="1" K="7000" damping="0.003" friction="0.2" mu_coulomb="0" mu_viscous="16"/>
  </joint>
  <!-- sub-link defining detailed meshes for collision with environment -->
  <link name="fer_link4">
    <visual name="fer_link4_visual">
      <geometry>
        <mesh filename="package://models/fer/meshes/visual/link4.dae"/>
      </geometry>
    </visual>
    <collision name="fer_link4_collision">
      <geometry>
        <mesh filename="package://models/fer/meshes/collision/link4.obj"/>
      </geometry>
    </collision>
    <inertial>
      <origin rpy="0 0 0" xyz="-5.317e-02 1.04419e-01 2.7454e-02"/>
      <mass value="3.587895"/>
      <inertia ixx="0.025853" ixy="0.007796" ixz="-0.001332" iyy="0.019552" iyz="0.008641" izz="0.028323"/>
    </inertial>
  </link>
  <joint name="fer_joint4" type="revolute">
    <origin rpy="1.570796326794897 0 0" xyz="0.0825 0 0"/>
    <parent link="fer_link3"/>
    <child link="fer_link4"/>
    <axis xyz="0 0 1"/>
    <limit effort="87.0" lower="-3.0718" upper="-0.0698" velocity="2.175"/>
    <safety_controller k_position="100.0" k_velocity="40.0" soft_lower_limit="-3.0718" soft_upper_limit="-0.0698"/>
    <dynamics D="1" K="7000" damping="0.003" friction="0.2" mu_coulomb="0" mu_viscous="16"/>
  </joint>
  <!-- sub-link defining detailed meshes for collision with environment -->
  <link name="fer_link5">
    <visual name="fer_link5_visual">
      <geometry>
        <mesh filename="package://models/fer/meshes/visual/link5.dae"/>
      </geometry>
    </visual>
    <collision name="fer_link5_collision">
      <geometry>
        <mesh filename="package://models/fer/meshes/collision/link5.obj"/>
      </geometry>
    </collision>
    <inertial>
      <origin rpy="0 0 0" xyz="-1.1953e-02 4.1065e-02 -3.8437e-02"/>
      <mass value="1.225946"/>
      <inertia ixx="0.035549" ixy="-0.002117" ixz="-0.004037" iyy="0.029474" iyz="0.000229" izz="0.008627"/>
    </inertial>
  </link>
  <joint name="fer_joint5" type="revolute">
    <origin rpy="-1.570796326794897 0 0" xyz="-0.0825 0.384 0"/>
    <parent link="fer_link4"/>
    <child link="fer_link5"/>
    <axis xyz="0 0 1"/>
    <limit effort="12.0" lower="-2.8973" upper="2.8973" velocity="2.61"/>
    <safety_controller k_position="100.0" k_velocity="40.0" soft_lower_limit="-2.8973" soft_upper_limit="2.8973"/>
    <dynamics D="1" K="7000" damping="0.003" friction="0.2" mu_coulomb="0" mu_viscous="16"/>
  </joint>
  <!-- sub-link defining detailed meshes for collision with environment -->
  <link name="fer_link6">
    <visual name="fer_link6_visual">
      <geometry>
        <mesh filename="package://models/fer/meshes/visual/link6.dae"/>
      </geometry>
    </visual>
    <collision name="fer_link6_collision">
      <geometry>
        <mesh filename="package://models/fer/meshes/collision/link6.obj"/>
      </geometry>
    </collision>
    <inertial>
      <origin rpy="0 0 0" xyz="6.0149e-02 -1.4117e-02 -1.0517e-02"/>
      <mass value="1.666555"/>
      <inertia ixx="0.001964" ixy="0.000109" ixz="-0.001158" iyy="0.004354" iyz="0.000341" izz="0.005433"/>
    </inertial>
  </link>
  <joint name="fer_joint6" type="revolute">
    <origin rpy="1.570796326794897 0 0" xyz="0 0 0"/>
    <parent link="fer_link5"/>
    <child link="fer_link6"/>
    <axis xyz="0 0 1"/>
    <limit effort="12.0" lower="-0.0175" upper="3.7525" velocity="2.61"/>
    <safety_controller k_position="100.0" k_velocity="40.0" soft_lower_limit="-0.0175" soft_upper_limit="3.7525"/>
    <dynamics D="1" K="7000" damping="0.003" friction="0.2" mu_coulomb="0" mu_viscous="16"/>
  </joint>
  <!-- sub-link defining detailed meshes for collision with environment -->
  <link name="fer_link7">
    <visual name="fer_link7_visual">
      <geometry>
        <mesh filename="package://models/fer/meshes/visual/link7.dae"/>
      </geometry>
    </visual>
    <collision name="fer_link7_collision">
      <geometry>
        <mesh filename="package://models/fer/meshes/collision/link7.obj"/>
      </geometry>
    </collision>
    <inertial>
      <origin rpy="0 0 0" xyz="1.0517e-02 -4.252e-03 6.1597e-02"/>
      <mass value="0.735522"/>
      <inertia ixx="0.012516" ixy="-0.000428" ixz="-0.001196" iyy="0.010027" iyz="-0.000741" izz="0.004815"/>
    </inertial>
  </link>
  <joint name="fer_joint7" type="revolute">
    <origin rpy="1.570796326794897 0 0" xyz="0.088 0 0"/>
    <parent link="fer_link6"/>
    <child link="fer_link7"/>
    <axis xyz="0 0 1"/>
    <limit effort="12.0" lower="-2.8973" upper="2.8973" velocity="2.61"/>
    <safety_controller k_position="100.0" k_velocity="40.0" soft_lower_limit="-2.8973" soft_upper_limit="2.8973"/>
    <dynamics D="1" K="7000" damping="0.003" friction="0.2" mu_coulomb="0" mu_viscous="16"/>
  </joint>
  <link name="fer_link8"/>
  <joint name="fer_joint8" type="fixed">
    <origin rpy="0 0 0" xyz="0 0 0.107"/>
    <parent link="fer_link7"/>
    <child link="fer_link8"/>
  </joint>
  <joint name="fer_ati_mini45_with_compact_camera_base_joint" type="fixed">
    <parent link="fer_link8"/>
    <child link="fer_ati_mini45_with_compact_camera"/>
    <origin rpy="0 0 -0.7853981633974483" xyz="0 0 0"/>
  </joint>
  <!-- sub-link defining detailed meshes for collision with environment -->
  <link name="fer_ati_mini45_with_compact_camera">
    <visual name="fer_ati_mini45_with_compact_camera_visual">
      <geometry>
        <mesh filename="package://models/fer/meshes/visual/ati_mini45_with_compact_camera.dae"/>
      </geometry>
    </visual>
    <collision name="fer_ati_mini45_with_compact_camera_collision">
      <geometry>
        <mesh filename="package://models/fer/meshes/collision/ati_mini45_with_compact_camera.obj"/>
      </geometry>
    </collision>
    <inertial>
      <origin rpy="0 0 0" xyz="0.0007 0.005 0.005"/>
      <mass value="0.195"/>
      <inertia ixx="0.00016863" ixy="-1.172e-05" ixz="3.621e-07" iyy="0.0001194" iyz="7.73e-06" izz="0.00025817"/>
    </inertial>
  </link>
  <joint name="ati_mini45_measurement_reference_joint" type="fixed">
    <parent link="fer_ati_mini45_with_compact_camera"/>
    <child link="ati_mini45_measurement_reference"/>
    <origin rpy="3.141592653589793 0.0 2.8797932657906435" xyz="0 0 0.017785"/>
  </joint>
  <link name="ati_mini45_measurement_reference"/>
  <joint name="fer_ati_mini45_with_compact_camera_tool_joint" type="fixed">
    <parent link="ati_mini45_measurement_reference"/>
    <child link="fer_ati_mini45_with_compact_camera_tool"/>
    <origin rpy="3.141592653589793 0.0 2.0943951023931953" xyz="0 0 -0.07885"/>
  </joint>
  <link name="fer_ati_mini45_with_compact_camera_tool">
    <collision name="fer_ati_mini45_with_compact_camera_collision">
      <geometry>
        <sphere radius="0.013"/>
      </geometry>
    </collision>
    <inertial>
      <origin rpy="0 0 0" xyz="0.0 0.0 -0.048"/>
      <mass value="0.165"/>
      <inertia ixx="0.00015969" ixy="1.368e-09" ixz="3.187e-09" iyy="0.00015945" iyz="4.844e-09" izz="4.036e-05"/>
    </inertial>
  </link>
  <link name="fer_ref_camera_link">
  </link>
  <joint name="fer_ref_camera_joint" type="fixed">
    <parent link="fer_ati_mini45_with_compact_camera"/>
    <child link="fer_ref_camera_link"/>
    <origin rpy="0.6014976125840796                       -1.5625012429015825                       -1.8273819833958986" xyz="0.010420172198562599                       0.05442028776489256                       0.010659522197016335"/>
  </joint>
  <material name="aluminum">
    <color rgba="0.5 0.5 0.5 1"/>
  </material>
  <material name="plastic">
    <color rgba="0.1 0.1 0.1 1"/>
  </material>
  <!-- camera body, with origin at bottom screw mount -->
  <joint name="camera_joint" type="fixed">
    <origin rpy="0 0 0" xyz="0 0 0"/>
    <parent link="fer_ref_camera_link"/>
    <child link="camera_bottom_screw_frame"/>
  </joint>
  <link name="camera_bottom_screw_frame"/>
  <joint name="camera_link_joint" type="fixed">
    <origin rpy="0 0 0" xyz="0.010600000000000002 0.0175 0.0125"/>
    <parent link="camera_bottom_screw_frame"/>
    <child link="camera_link"/>
  </joint>
  <link name="camera_link">
    <visual>
      <!-- the mesh origin is at front plate in between the two infrared camera axes -->
      <origin rpy="1.5707963267948966 0 1.5707963267948966" xyz="0.0043 -0.0175 0"/>
      <geometry>
        <mesh filename="package://models/fer/meshes/visual/d435.dae"/>
      </geometry>
    </visual>
    <collision>
      <origin rpy="0 0 0" xyz="0 -0.0175 0"/>
      <geometry>
        <box size="0.02505 0.09 0.025"/>
      </geometry>
    </collision>
    <inertial>
      <!-- The following are not reliable values, and should not be used for modeling -->
      <mass value="0.072"/>
      <origin xyz="0 0 0"/>
      <inertia ixx="0.003881243" ixy="0.0" ixz="0.0" iyy="0.000498940" iyz="0.0" izz="0.003879257"/>
    </inertial>
  </link>
  <!-- camera depth joints and links -->
  <joint name="camera_depth_joint" type="fixed">
    <origin rpy="0 0 0" xyz="0 0 0"/>
    <parent link="camera_link"/>
    <child link="camera_depth_frame"/>
  </joint>
  <link name="camera_depth_frame"/>
  <joint name="camera_depth_optical_joint" type="fixed">
    <origin rpy="-1.5707963267948966 0 -1.5707963267948966" xyz="0 0 0"/>
    <parent link="camera_depth_frame"/>
    <child link="camera_depth_optical_frame"/>
  </joint>
  <link name="camera_depth_optical_frame"/>
  <!-- camera left IR joints and links -->
  <joint name="camera_infra1_joint" type="fixed">
    <origin rpy="0 0 0" xyz="0 0.0 0"/>
    <parent link="camera_link"/>
    <child link="camera_infra1_frame"/>
  </joint>
  <link name="camera_infra1_frame"/>
  <joint name="camera_infra1_optical_joint" type="fixed">
    <origin rpy="-1.5707963267948966 0 -1.5707963267948966" xyz="0 0 0"/>
    <parent link="camera_infra1_frame"/>
    <child link="camera_infra1_optical_frame"/>
  </joint>
  <link name="camera_infra1_optical_frame"/>
  <!-- camera right IR joints and links -->
  <joint name="camera_infra2_joint" type="fixed">
    <origin rpy="0 0 0" xyz="0 -0.05 0"/>
    <parent link="camera_link"/>
    <child link="camera_infra2_frame"/>
  </joint>
  <link name="camera_infra2_frame"/>
  <joint name="camera_infra2_optical_joint" type="fixed">
    <origin rpy="-1.5707963267948966 0 -1.5707963267948966" xyz="0 0 0"/>
    <parent link="camera_infra2_frame"/>
    <child link="camera_infra2_optical_frame"/>
  </joint>
  <link name="camera_infra2_optical_frame"/>
  <!-- camera color joints and links -->
  <joint name="camera_color_joint" type="fixed">
    <origin rpy="0 0 0" xyz="0 0.015 0"/>
    <parent link="camera_link"/>
    <child link="camera_color_frame"/>
  </joint>
  <link name="camera_color_frame"/>
  <joint name="camera_color_optical_joint" type="fixed">
    <origin rpy="-1.5707963267948966 0 -1.5707963267948966" xyz="0 0 0"/>
    <parent link="camera_color_frame"/>
    <child link="camera_color_optical_frame"/>
  </joint>
  <link name="camera_color_optical_frame"/>
  <link name="world"/>
  <joint name="world_joint" type="fixed">
    <origin rpy="0 0 0" xyz="0 0 0"/>
    <parent link="world"/>
    <child link="fer_link0"/>
  </joint>
  <gazebo reference="fer_joint1">
    <!-- Needed for ODE to output external wrenches on joints -->
    <provideFeedback>true</provideFeedback>
  </gazebo>
  <transmission name="fer_joint1_transmission">
    <type>transmission_interface/SimpleTransmission</type>
    <joint name="fer_joint1">
      <hardwareInterface>hardware_interface/PositionJointInterface</hardwareInterface>
    </joint>
    <actuator name="fer_joint1_motor">
      <hardwareInterface>hardware_interface/PositionJointInterface</hardwareInterface>
    </actuator>
  </transmission>
  <gazebo reference="fer_joint2">
    <!-- Needed for ODE to output external wrenches on joints -->
    <provideFeedback>true</provideFeedback>
  </gazebo>
  <transmission name="fer_joint2_transmission">
    <type>transmission_interface/SimpleTransmission</type>
    <joint name="fer_joint2">
      <hardwareInterface>hardware_interface/PositionJointInterface</hardwareInterface>
    </joint>
    <actuator name="fer_joint2_motor">
      <hardwareInterface>hardware_interface/PositionJointInterface</hardwareInterface>
    </actuator>
  </transmission>
  <gazebo reference="fer_joint3">
    <!-- Needed for ODE to output external wrenches on joints -->
    <provideFeedback>true</provideFeedback>
  </gazebo>
  <transmission name="fer_joint3_transmission">
    <type>transmission_interface/SimpleTransmission</type>
    <joint name="fer_joint3">
      <hardwareInterface>hardware_interface/PositionJointInterface</hardwareInterface>
    </joint>
    <actuator name="fer_joint3_motor">
      <hardwareInterface>hardware_interface/PositionJointInterface</hardwareInterface>
    </actuator>
  </transmission>
  <gazebo reference="fer_joint4">
    <!-- Needed for ODE to output external wrenches on joints -->
    <provideFeedback>true</provideFeedback>
  </gazebo>
  <transmission name="fer_joint4_transmission">
    <type>transmission_interface/SimpleTransmission</type>
    <joint name="fer_joint4">
      <hardwareInterface>hardware_interface/PositionJointInterface</hardwareInterface>
    </joint>
    <actuator name="fer_joint4_motor">
      <hardwareInterface>hardware_interface/PositionJointInterface</hardwareInterface>
    </actuator>
  </transmission>
  <gazebo reference="fer_joint5">
    <!-- Needed for ODE to output external wrenches on joints -->
    <provideFeedback>true</provideFeedback>
  </gazebo>
  <transmission name="fer_joint5_transmission">
    <type>transmission_interface/SimpleTransmission</type>
    <joint name="fer_joint5">
      <hardwareInterface>hardware_interface/PositionJointInterface</hardwareInterface>
    </joint>
    <actuator name="fer_joint5_motor">
      <hardwareInterface>hardware_interface/PositionJointInterface</hardwareInterface>
    </actuator>
  </transmission>
  <gazebo reference="fer_joint6">
    <!-- Needed for ODE to output external wrenches on joints -->
    <provideFeedback>true</provideFeedback>
  </gazebo>
  <transmission name="fer_joint6_transmission">
    <type>transmission_interface/SimpleTransmission</type>
    <joint name="fer_joint6">
      <hardwareInterface>hardware_interface/PositionJointInterface</hardwareInterface>
    </joint>
    <actuator name="fer_joint6_motor">
      <hardwareInterface>hardware_interface/PositionJointInterface</hardwareInterface>
    </actuator>
  </transmission>
  <gazebo reference="fer_joint7">
    <!-- Needed for ODE to output external wrenches on joints -->
    <provideFeedback>true</provideFeedback>
  </gazebo>
  <transmission name="fer_joint7_transmission">
    <type>transmission_interface/SimpleTransmission</type>
    <joint name="fer_joint7">
      <hardwareInterface>hardware_interface/PositionJointInterface</hardwareInterface>
    </joint>
    <actuator name="fer_joint7_motor">
      <hardwareInterface>hardware_interface/PositionJointInterface</hardwareInterface>
    </actuator>
  </transmission>
  <gazebo reference="fer_joint1">
    <!-- Needed for ODE to output external wrenches on joints -->
    <provideFeedback>true</provideFeedback>
  </gazebo>
  <transmission name="fer_joint1_transmission">
    <type>transmission_interface/SimpleTransmission</type>
    <joint name="fer_joint1">
      <hardwareInterface>hardware_interface/VelocityJointInterface</hardwareInterface>
    </joint>
    <actuator name="fer_joint1_motor">
      <hardwareInterface>hardware_interface/VelocityJointInterface</hardwareInterface>
    </actuator>
  </transmission>
  <gazebo reference="fer_joint2">
    <!-- Needed for ODE to output external wrenches on joints -->
    <provideFeedback>true</provideFeedback>
  </gazebo>
  <transmission name="fer_joint2_transmission">
    <type>transmission_interface/SimpleTransmission</type>
    <joint name="fer_joint2">
      <hardwareInterface>hardware_interface/VelocityJointInterface</hardwareInterface>
    </joint>
    <actuator name="fer_joint2_motor">
      <hardwareInterface>hardware_interface/VelocityJointInterface</hardwareInterface>
    </actuator>
  </transmission>
  <gazebo reference="fer_joint3">
    <!-- Needed for ODE to output external wrenches on joints -->
    <provideFeedback>true</provideFeedback>
  </gazebo>
  <transmission name="fer_joint3_transmission">
    <type>transmission_interface/SimpleTransmission</type>
    <joint name="fer_joint3">
      <hardwareInterface>hardware_interface/VelocityJointInterface</hardwareInterface>
    </joint>
    <actuator name="fer_joint3_motor">
      <hardwareInterface>hardware_interface/VelocityJointInterface</hardwareInterface>
    </actuator>
  </transmission>
  <gazebo reference="fer_joint4">
    <!-- Needed for ODE to output external wrenches on joints -->
    <provideFeedback>true</provideFeedback>
  </gazebo>
  <transmission name="fer_joint4_transmission">
    <type>transmission_interface/SimpleTransmission</type>
    <joint name="fer_joint4">
      <hardwareInterface>hardware_interface/VelocityJointInterface</hardwareInterface>
    </joint>
    <actuator name="fer_joint4_motor">
      <hardwareInterface>hardware_interface/VelocityJointInterface</hardwareInterface>
    </actuator>
  </transmission>
  <gazebo reference="fer_joint5">
    <!-- Needed for ODE to output external wrenches on joints -->
    <provideFeedback>true</provideFeedback>
  </gazebo>
  <transmission name="fer_joint5_transmission">
    <type>transmission_interface/SimpleTransmission</type>
    <joint name="fer_joint5">
      <hardwareInterface>hardware_interface/VelocityJointInterface</hardwareInterface>
    </joint>
    <actuator name="fer_joint5_motor">
      <hardwareInterface>hardware_interface/VelocityJointInterface</hardwareInterface>
    </actuator>
  </transmission>
  <gazebo reference="fer_joint6">
    <!-- Needed for ODE to output external wrenches on joints -->
    <provideFeedback>true</provideFeedback>
  </gazebo>
  <transmission name="fer_joint6_transmission">
    <type>transmission_interface/SimpleTransmission</type>
    <joint name="fer_joint6">
      <hardwareInterface>hardware_interface/VelocityJointInterface</hardwareInterface>
    </joint>
    <actuator name="fer_joint6_motor">
      <hardwareInterface>hardware_interface/VelocityJointInterface</hardwareInterface>
    </actuator>
  </transmission>
  <gazebo reference="fer_joint7">
    <!-- Needed for ODE to output external wrenches on joints -->
    <provideFeedback>true</provideFeedback>
  </gazebo>
  <transmission name="fer_joint7_transmission">
    <type>transmission_interface/SimpleTransmission</type>
    <joint name="fer_joint7">
      <hardwareInterface>hardware_interface/VelocityJointInterface</hardwareInterface>
    </joint>
    <actuator name="fer_joint7_motor">
      <hardwareInterface>hardware_interface/VelocityJointInterface</hardwareInterface>
    </actuator>
  </transmission>
  <gazebo reference="fer_joint1">
    <!-- Needed for ODE to output external wrenches on joints -->
    <provideFeedback>true</provideFeedback>
  </gazebo>
  <transmission name="fer_joint1_transmission">
    <type>transmission_interface/SimpleTransmission</type>
    <joint name="fer_joint1">
      <hardwareInterface>hardware_interface/EffortJointInterface</hardwareInterface>
    </joint>
    <actuator name="fer_joint1_motor">
      <hardwareInterface>hardware_interface/EffortJointInterface</hardwareInterface>
    </actuator>
  </transmission>
  <gazebo reference="fer_joint2">
    <!-- Needed for ODE to output external wrenches on joints -->
    <provideFeedback>true</provideFeedback>
  </gazebo>
  <transmission name="fer_joint2_transmission">
    <type>transmission_interface/SimpleTransmission</type>
    <joint name="fer_joint2">
      <hardwareInterface>hardware_interface/EffortJointInterface</hardwareInterface>
    </joint>
    <actuator name="fer_joint2_motor">
      <hardwareInterface>hardware_interface/EffortJointInterface</hardwareInterface>
    </actuator>
  </transmission>
  <gazebo reference="fer_joint3">
    <!-- Needed for ODE to output external wrenches on joints -->
    <provideFeedback>true</provideFeedback>
  </gazebo>
  <transmission name="fer_joint3_transmission">
    <type>transmission_interface/SimpleTransmission</type>
    <joint name="fer_joint3">
      <hardwareInterface>hardware_interface/EffortJointInterface</hardwareInterface>
    </joint>
    <actuator name="fer_joint3_motor">
      <hardwareInterface>hardware_interface/EffortJointInterface</hardwareInterface>
    </actuator>
  </transmission>
  <gazebo reference="fer_joint4">
    <!-- Needed for ODE to output external wrenches on joints -->
    <provideFeedback>true</provideFeedback>
  </gazebo>
  <transmission name="fer_joint4_transmission">
    <type>transmission_interface/SimpleTransmission</type>
    <joint name="fer_joint4">
      <hardwareInterface>hardware_interface/EffortJointInterface</hardwareInterface>
    </joint>
    <actuator name="fer_joint4_motor">
      <hardwareInterface>hardware_interface/EffortJointInterface</hardwareInterface>
    </actuator>
  </transmission>
  <gazebo reference="fer_joint5">
    <!-- Needed for ODE to output external wrenches on joints -->
    <provideFeedback>true</provideFeedback>
  </gazebo>
  <transmission name="fer_joint5_transmission">
    <type>transmission_interface/SimpleTransmission</type>
    <joint name="fer_joint5">
      <hardwareInterface>hardware_interface/EffortJointInterface</hardwareInterface>
    </joint>
    <actuator name="fer_joint5_motor">
      <hardwareInterface>hardware_interface/EffortJointInterface</hardwareInterface>
    </actuator>
  </transmission>
  <gazebo reference="fer_joint6">
    <!-- Needed for ODE to output external wrenches on joints -->
    <provideFeedback>true</provideFeedback>
  </gazebo>
  <transmission name="fer_joint6_transmission">
    <type>transmission_interface/SimpleTransmission</type>
    <joint name="fer_joint6">
      <hardwareInterface>hardware_interface/EffortJointInterface</hardwareInterface>
    </joint>
    <actuator name="fer_joint6_motor">
      <hardwareInterface>hardware_interface/EffortJointInterface</hardwareInterface>
    </actuator>
  </transmission>
  <gazebo reference="fer_joint7">
    <!-- Needed for ODE to output external wrenches on joints -->
    <provideFeedback>true</provideFeedback>
  </gazebo>
  <transmission name="fer_joint7_transmission">
    <type>transmission_interface/SimpleTransmission</type>
    <joint name="fer_joint7">
      <hardwareInterface>hardware_interface/EffortJointInterface</hardwareInterface>
    </joint>
    <actuator name="fer_joint7_motor">
      <hardwareInterface>hardware_interface/EffortJointInterface</hardwareInterface>
    </actuator>
  </transmission>
  <transmission name="fer_franka_state">
    <type>franka_hw/FrankaStateInterface</type>
    <joint name="fer_joint1">
      <hardwareInterface>franka_hw/FrankaStateInterface</hardwareInterface>
    </joint>
    <joint name="fer_joint2">
      <hardwareInterface>franka_hw/FrankaStateInterface</hardwareInterface>
    </joint>
    <joint name="fer_joint3">
      <hardwareInterface>franka_hw/FrankaStateInterface</hardwareInterface>
    </joint>
    <joint name="fer_joint4">
      <hardwareInterface>franka_hw/FrankaStateInterface</hardwareInterface>
    </joint>
    <joint name="fer_joint5">
      <hardwareInterface>franka_hw/FrankaStateInterface</hardwareInterface>
    </joint>
    <joint name="fer_joint6">
      <hardwareInterface>franka_hw/FrankaStateInterface</hardwareInterface>
    </joint>
    <joint name="fer_joint7">
      <hardwareInterface>franka_hw/FrankaStateInterface</hardwareInterface>
    </joint>
    <actuator name="fer_motor1">
      <hardwareInterface>franka_hw/FrankaStateInterface</hardwareInterface>
    </actuator>
    <actuator name="fer_motor2">
      <hardwareInterface>franka_hw/FrankaStateInterface</hardwareInterface>
    </actuator>
    <actuator name="fer_motor3">
      <hardwareInterface>franka_hw/FrankaStateInterface</hardwareInterface>
    </actuator>
    <actuator name="fer_motor4">
      <hardwareInterface>franka_hw/FrankaStateInterface</hardwareInterface>
    </actuator>
    <actuator name="fer_motor5">
      <hardwareInterface>franka_hw/FrankaStateInterface</hardwareInterface>
    </actuator>
    <actuator name="fer_motor6">
      <hardwareInterface>franka_hw/FrankaStateInterface</hardwareInterface>
    </actuator>
    <actuator name="fer_motor7">
      <hardwareInterface>franka_hw/FrankaStateInterface</hardwareInterface>
    </actuator>
  </transmission>
  <transmission name="fer_franka_model">
    <type>franka_hw/FrankaModelInterface</type>
    <joint name="fer_joint1">
      <role>root</role>
      <hardwareInterface>franka_hw/FrankaModelInterface</hardwareInterface>
    </joint>
    <joint name="fer_joint8">
      <role>tip</role>
      <hardwareInterface>franka_hw/FrankaModelInterface</hardwareInterface>
    </joint>
    <actuator name="fer_joint1_motor_root">
      <hardwareInterface>franka_hw/FrankaModelInterface</hardwareInterface>
    </actuator>
    <actuator name="fer_joint8_motor_tip">
      <hardwareInterface>franka_hw/FrankaModelInterface</hardwareInterface>
    </actuator>
  </transmission>
  <ros2_control name="FrankaHardwareInterface" type="system">
    <hardware>
      <param name="arm_id">fer</param>
      <param name="prefix"></param>
      <plugin>franka_ign_ros2_control/IgnitionSystem</plugin>
    </hardware>
    <joint name="fer_joint1">
      <command_interface name="position"/>
      <command_interface name="velocity"/>
      <command_interface name="effort"/>
      <!-- State Interfaces -->
      <state_interface name="position">
        <param name="initial_value">0.78</param>
      </state_interface>
      <state_interface name="velocity"/>
      <param name="initial_value">0.0</param>
      <state_interface name="effort"/>
    </joint>
    <joint name="fer_joint2">
      <command_interface name="position"/>
      <command_interface name="velocity"/>
      <command_interface name="effort"/>
      <!-- State Interfaces -->
      <state_interface name="position">
        <param name="initial_value">-0.78</param>
      </state_interface>
      <state_interface name="velocity"/>
      <param name="initial_value">0.0</param>
      <state_interface name="effort"/>
    </joint>
    <joint name="fer_joint3">
      <command_interface name="position"/>
      <command_interface name="velocity"/>
      <command_interface name="effort"/>
      <!-- State Interfaces -->
      <state_interface name="position">
        <param name="initial_value">0.0</param>
      </state_interface>
      <state_interface name="velocity"/>
      <param name="initial_value">0.0</param>
      <state_interface name="effort"/>
    </joint>
    <joint name="fer_joint4">
      <command_interface name="position"/>
      <command_interface name="velocity"/>
      <command_interface name="effort"/>
      <!-- State Interfaces -->
      <state_interface name="position">
        <param name="initial_value">-2.35</param>
      </state_interface>
      <state_interface name="velocity"/>
      <param name="initial_value">0.0</param>
      <state_interface name="effort"/>
    </joint>
    <joint name="fer_joint5">
      <command_interface name="position"/>
      <command_interface name="velocity"/>
      <command_interface name="effort"/>
      <!-- State Interfaces -->
      <state_interface name="position">
        <param name="initial_value">0.0</param>
      </state_interface>
      <state_interface name="velocity"/>
      <param name="initial_value">0.0</param>
      <state_interface name="effort"/>
    </joint>
    <joint name="fer_joint6">
      <command_interface name="position"/>
      <command_interface name="velocity"/>
      <command_interface name="effort"/>
      <!-- State Interfaces -->
      <state_interface name="position">
        <param name="initial_value">1.57</param>
      </state_interface>
      <state_interface name="velocity"/>
      <param name="initial_value">0.0</param>
      <state_interface name="effort"/>
    </joint>
    <joint name="fer_joint7">
      <command_interface name="position"/>
      <command_interface name="velocity"/>
      <command_interface name="effort"/>
      <!-- State Interfaces -->
      <state_interface name="position">
        <param name="initial_value">0.78</param>
      </state_interface>
      <state_interface name="velocity"/>
      <param name="initial_value">0.0</param>
      <state_interface name="effort"/>
    </joint>
    <joint name="fer_finger_joint1">
      <command_interface name="position"/>
      <command_interface name="velocity"/>
      <command_interface name="effort"/>
      <!-- State Interfaces -->
      <state_interface name="position">
        <param name="initial_value">0.0</param>
      </state_interface>
      <state_interface name="velocity"/>
      <param name="initial_value">0.0</param>
      <state_interface name="effort"/>
    </joint>
    <joint name="fer_finger_joint2">
      <command_interface name="position"/>
      <command_interface name="velocity"/>
      <command_interface name="effort"/>
      <!-- State Interfaces -->
      <state_interface name="position">
      </state_interface>
      <state_interface name="velocity"/>
      <param name="initial_value">0.0</param>
      <state_interface name="effort"/>
      <param name="mimic">fer_finger_joint1</param>
      <param name="multiplier">1</param>
    </joint>
    <sensor name="ati_mini45">
      <state_interface name="force.x"/>
      <state_interface name="force.y"/>
      <state_interface name="force.z"/>
      <state_interface name="torque.x"/>
      <state_interface name="torque.y"/>
      <state_interface name="torque.z"/>
      <param name="frame_id">ati_mini45_measurement_reference</param>
    </sensor>
  </ros2_control>
  <gazebo>
    <plugin filename="franka_ign_ros2_control-system" name="ign_ros2_control::IgnitionROS2ControlPlugin">
      <parameters>/home/gepetto/ros2_ws/install/agimus_demos_common/share/agimus_demos_common/config/franka/controllers.yaml</parameters>
      <ros>
        <remapping>/joint_states:=/franka/joint_states</remapping>
        <!-- Remapping of actions doesn't seem to work all that well so we need to map every topic and service manually -->
        <!-- Solved in https://github.com/ros2/rcl/pull/1170 but was not backported to humble and not even to jazzy -->
        <remapping>/gripper_action_controller/gripper_cmd/_action/feedback:=/fer_gripper/gripper_action/_action/feedback</remapping>
        <remapping>/gripper_action_controller/gripper_cmd/_action/status:=/fer_gripper/gripper_action/_action/status</remapping>
        <remapping>/gripper_action_controller/gripper_cmd/_action/cancel_goal:=/fer_gripper/gripper_action/_action/cancel_goal</remapping>
        <remapping>/gripper_action_controller/gripper_cmd/_action/get_result:=/fer_gripper/gripper_action/_action/get_result</remapping>
        <remapping>/gripper_action_controller/gripper_cmd/_action/send_goal:=/fer_gripper/gripper_action/_action/send_goal</remapping>
      </ros>
    </plugin>
  </gazebo>
  <plugin filename="ignition-gazebo-forcetorque-system" name="ignition::gazebo::systems::ForceTorque"/>
  <!-- For now ft-sensor in gazebo doesn't seem to work. Even though the syntax for the sensor seems to match-->
  <!-- what can be found in unit tests of the Gazebo and sensor is registered in the UI of Gazebo. -->
  <gazebo reference="ati_mini45_measurement_reference_joint">
    <provideFeedback>true</provideFeedback>
    <preserveFixedJoint>true</preserveFixedJoint>
    <sensor name="ati_mini45" type="force_torque">
      <alwaysOn>true</alwaysOn>
      <update_rate>1000</update_rate>
      <visualize>true</visualize>
      <frame>ati_mini45_measurement_reference</frame>
      <ignition_frame_id>ati_mini45_measurement_reference</ignition_frame_id>
      <topic>force_torque</topic>
      <force_torque>
        <frame>parent</frame>
        <measure_direction>child_to_parent</measure_direction>
        <!-- Values measured on the real sensor -->
        <force>
          <!-- N -->
          <x>
            <noise type="gaussian">
              <mean>0.0</mean>
              <stddev>0.2381</stddev>
              <bias_mean>0.0</bias_mean>
              <bias_stddev>0.0</bias_stddev>
            </noise>
          </x>
          <y>
            <noise type="gaussian">
              <mean>0.0</mean>
              <stddev>0.20312</stddev>
              <bias_mean>0.0</bias_mean>
              <bias_stddev>0.0</bias_stddev>
            </noise>
          </y>
          <z>
            <noise type="gaussian">
              <mean>0.0</mean>
              <stddev>0.40506</stddev>
              <bias_mean>0.0</bias_mean>
              <bias_stddev>0.0</bias_stddev>
            </noise>
          </z>
        </force>
        <torque>
          <!-- Nm -->
          <x>
            <noise type="gaussian">
              <mean>0.0</mean>
              <stddev>0.00167</stddev>
              <bias_mean>0.0</bias_mean>
              <bias_stddev>0.0</bias_stddev>
            </noise>
          </x>
          <y>
            <noise type="gaussian">
              <mean>0.0</mean>
              <stddev>0.00096</stddev>
              <bias_mean>0.0</bias_mean>
              <bias_stddev>0.0</bias_stddev>
            </noise>
          </y>
          <z>
            <noise type="gaussian">
              <mean>0.0</mean>
              <stddev>0.00267</stddev>
              <bias_mean>0.0</bias_mean>
              <bias_stddev>0.0</bias_stddev>
            </noise>
          </z>
        </torque>
      </force_torque>
    </sensor>
  </gazebo>
</robot>
